,caller,exception
0,test_s-2,"Traceback (most recent call last):
  File ""C:\Users\John\Documents\GitHub\HOPP\alt_dev\optimization_driver_alt.py"", line 615, in s_wrapper
    result = self.cache[candidate]
  File ""C:\Users\John\anaconda3\envs\HOPP\lib\site-packages\diskcache\core.py"", line 1240, in __getitem__
    raise KeyError(key)
KeyError: (('tower::cycle_capacity_kw', 125000.0), ('tower::solar_multiple', 1.5), ('tower::tes_hours', 12.666666666666666), ('pv::system_capacity_kw', 25000.0), ('pv::tilt', 15.0))

During handling of the above exception, another exception occurred:

Traceback (most recent call last):
  File ""C:\Users\John\Documents\GitHub\HOPP\alt_dev\optimization_problem_alt.py"", line 212, in evaluate_objective
    self.simulation.simulate()
  File ""C:\Users\John\Documents\GitHub\HOPP\hybrid\hybrid_simulation.py"", line 382, in simulate
    model.simulate(project_life, skip_sim)
  File ""C:\Users\John\Documents\GitHub\HOPP\hybrid\power_source.py"", line 161, in simulate
    self._system_model.execute(0)
Exception: pvwattsv7 execution error.
	precheck input: variable 'dc_degradation' (Annual DC degradation for lifetime simulations) required but not assigned


"
